Traceback (most recent call last):
  File "/usr/local/python/3.12.1/lib/python3.12/site-packages/jupyter_cache/executors/utils.py", line 58, in single_nb_execution
    executenb(
  File "/home/codespace/.local/lib/python3.12/site-packages/nbclient/client.py", line 1314, in execute
    return NotebookClient(nb=nb, resources=resources, km=km, **kwargs).execute()
           ^^^^^^^^^^^^^^^^^^^^^^^^^^^^^^^^^^^^^^^^^^^^^^^^^^^^^^^^^^^^^^^^^^^^^
  File "/home/codespace/.local/lib/python3.12/site-packages/jupyter_core/utils/__init__.py", line 165, in wrapped
    return loop.run_until_complete(inner)
           ^^^^^^^^^^^^^^^^^^^^^^^^^^^^^^
  File "/usr/local/python/3.12.1/lib/python3.12/asyncio/base_events.py", line 684, in run_until_complete
    return future.result()
           ^^^^^^^^^^^^^^^
  File "/home/codespace/.local/lib/python3.12/site-packages/nbclient/client.py", line 709, in async_execute
    await self.async_execute_cell(
  File "/home/codespace/.local/lib/python3.12/site-packages/nbclient/client.py", line 1062, in async_execute_cell
    await self._check_raise_for_error(cell, cell_index, exec_reply)
  File "/home/codespace/.local/lib/python3.12/site-packages/nbclient/client.py", line 918, in _check_raise_for_error
    raise CellExecutionError.from_cell_and_msg(cell, exec_reply_content)
nbclient.exceptions.CellExecutionError: An error occurred while executing the following cell:
------------------
# import required packages
import json
import os
from datetime import datetime as dt
import warnings
warnings.filterwarnings('ignore')
import matplotlib.pyplot as plt
from alpineer import io_utils, load_utils
from matplotlib import rc_file_defaults
import pandas as pd
import numpy as np
import pyFlowSOM
import seaborn as sns
from matplotlib.colors import ListedColormap
from tifffile import imread
from tqdm.notebook import tqdm
import stackview

from ark.phenotyping import (pixel_cluster_utils, pixel_meta_clustering,
                             pixel_som_clustering, pixie_preprocessing)
from ark.utils import data_utils
from ark.utils import plot_utils
from ark.utils.metacluster_remap_gui import (MetaClusterGui,
                                             colormap_helper,
                                             metaclusterdata_from_files)
------------------


[0;31m---------------------------------------------------------------------------[0m
[0;31mModuleNotFoundError[0m                       Traceback (most recent call last)
Cell [0;32mIn[1], line 8[0m
[1;32m      6[0m warnings[38;5;241m.[39mfilterwarnings([38;5;124m'[39m[38;5;124mignore[39m[38;5;124m'[39m)
[1;32m      7[0m [38;5;28;01mimport[39;00m [38;5;21;01mmatplotlib[39;00m[38;5;21;01m.[39;00m[38;5;21;01mpyplot[39;00m [38;5;28;01mas[39;00m [38;5;21;01mplt[39;00m
[0;32m----> 8[0m [38;5;28;01mfrom[39;00m [38;5;21;01malpineer[39;00m [38;5;28;01mimport[39;00m io_utils, load_utils
[1;32m      9[0m [38;5;28;01mfrom[39;00m [38;5;21;01mmatplotlib[39;00m [38;5;28;01mimport[39;00m rc_file_defaults
[1;32m     10[0m [38;5;28;01mimport[39;00m [38;5;21;01mpandas[39;00m [38;5;28;01mas[39;00m [38;5;21;01mpd[39;00m

File [0;32m/workspaces/KINTSUGI-docs/src/notebooks/alpineer/load_utils.py:8[0m
[1;32m      5[0m [38;5;28;01mfrom[39;00m [38;5;21;01mtyping[39;00m [38;5;28;01mimport[39;00m List, Optional, OrderedDict, Union
[1;32m      7[0m [38;5;28;01mimport[39;00m [38;5;21;01mnumpy[39;00m [38;5;28;01mas[39;00m [38;5;21;01mnp[39;00m
[0;32m----> 8[0m [38;5;28;01mimport[39;00m [38;5;21;01mskimage[39;00m[38;5;21;01m.[39;00m[38;5;21;01mio[39;00m [38;5;28;01mas[39;00m [38;5;21;01mio[39;00m
[1;32m      9[0m [38;5;28;01mimport[39;00m [38;5;21;01mxarray[39;00m [38;5;28;01mas[39;00m [38;5;21;01mxr[39;00m
[1;32m     10[0m [38;5;28;01mimport[39;00m [38;5;21;01mxmltodict[39;00m

[0;31mModuleNotFoundError[0m: No module named 'skimage'

