Traceback (most recent call last):
  File "C:\Users\smith6jt\miniforge3\envs\KINTSUGI\lib\site-packages\jupyter_cache\executors\utils.py", line 58, in single_nb_execution
    executenb(
  File "C:\Users\smith6jt\miniforge3\envs\KINTSUGI\lib\site-packages\nbclient\client.py", line 1314, in execute
    return NotebookClient(nb=nb, resources=resources, km=km, **kwargs).execute()
  File "C:\Users\smith6jt\miniforge3\envs\KINTSUGI\lib\site-packages\jupyter_core\utils\__init__.py", line 165, in wrapped
    return loop.run_until_complete(inner)
  File "C:\Users\smith6jt\miniforge3\envs\KINTSUGI\lib\asyncio\base_events.py", line 647, in run_until_complete
    return future.result()
  File "C:\Users\smith6jt\miniforge3\envs\KINTSUGI\lib\site-packages\nbclient\client.py", line 709, in async_execute
    await self.async_execute_cell(
  File "C:\Users\smith6jt\miniforge3\envs\KINTSUGI\lib\site-packages\nbclient\client.py", line 1062, in async_execute_cell
    await self._check_raise_for_error(cell, cell_index, exec_reply)
  File "C:\Users\smith6jt\miniforge3\envs\KINTSUGI\lib\site-packages\nbclient\client.py", line 918, in _check_raise_for_error
    raise CellExecutionError.from_cell_and_msg(cell, exec_reply_content)
nbclient.exceptions.CellExecutionError: An error occurred while executing the following cell:
------------------
tile(proc_dir, tiff_dir)
------------------


[1;31m---------------------------------------------------------------------------[0m
[1;31mPermissionError[0m                           Traceback (most recent call last)
Cell [1;32mIn[6], line 1[0m
[1;32m----> 1[0m [43mtile[49m[43m([49m[43mproc_dir[49m[43m,[49m[43m [49m[43mtiff_dir[49m[43m)[49m

Cell [1;32mIn[5], line 5[0m, in [0;36mtile[1;34m(input_folder, output_folder_base)[0m
[0;32m      3[0m files [38;5;241m=[39m os[38;5;241m.[39mlistdir(input_folder)
[0;32m      4[0m filename [38;5;241m=[39m os[38;5;241m.[39mpath[38;5;241m.[39mjoin(input_folder, files[[38;5;241m0[39m])
[1;32m----> 5[0m image [38;5;241m=[39m [43mImage[49m[38;5;241;43m.[39;49m[43mopen[49m[43m([49m[43mfilename[49m[43m)[49m
[0;32m      6[0m [38;5;28mprint[39m([38;5;124mf[39m[38;5;124m"[39m[38;5;124mUsing [39m[38;5;132;01m{[39;00mfilename[38;5;132;01m}[39;00m[38;5;124m for image dimensions.[39m[38;5;124m"[39m)
[0;32m      7[0m img_width, img_height [38;5;241m=[39m image[38;5;241m.[39msize

File [1;32m~\miniforge3\envs\KINTSUGI\lib\site-packages\PIL\Image.py:3236[0m, in [0;36mopen[1;34m(fp, mode, formats)[0m
[0;32m   3233[0m     filename [38;5;241m=[39m fp
[0;32m   3235[0m [38;5;28;01mif[39;00m filename:
[1;32m-> 3236[0m     fp [38;5;241m=[39m [43mbuiltins[49m[38;5;241;43m.[39;49m[43mopen[49m[43m([49m[43mfilename[49m[43m,[49m[43m [49m[38;5;124;43m"[39;49m[38;5;124;43mrb[39;49m[38;5;124;43m"[39;49m[43m)[49m
[0;32m   3237[0m     exclusive_fp [38;5;241m=[39m [38;5;28;01mTrue[39;00m
[0;32m   3239[0m [38;5;28;01mtry[39;00m:

[1;31mPermissionError[0m: [Errno 13] Permission denied: 'C:/Users/smith6jt/KINTSUGI/data/1904_CC2B_Processed\\PostProcessing'

